Workbook
Name filtered_headers: _xlfn._xlws.FILTER(netflixPart2!XEZ1:A1,ISNA(_xlfn.XMATCH(netflixPart2!XEZ1:A1,netflixPart1!XEZ1:XFD1)))

Sheet netflixPart2
A1: show_id | B1: date_added | C1: release_year | D1: rating | E1: duration | F1: listed_in
A2: s1 | B2: 9/25/2021 | C2: 2020 | D2: PG-13 | E2: 90 min | F2: Documentaries
A3: s3 | B3: 9/24/2021 | C3: 2021 | D3: TV-MA | E3: 1 Season | F3: Crime TV Shows, International TV Shows, TV Action & Adventure
A4: s6 | B4: 9/24/2021 | C4: 2021 | D4: TV-MA | E4: 1 Season | F4: TV Dramas, TV Horror, TV Mysteries
A5: s14 | B5: 9/22/2021 | C5: 2021 | D5: TV-PG | E5: 91 min | F5: Children & Family Movies, Comedies
A6: s8 | B6: 9/24/2021 | C6: 1993 | D6: TV-MA | E6: 125 min | F6: Dramas, Independent Movies, International Movies
A7: s9 | B7: 9/24/2021 | C7: 2021 | D7: TV-14 | E7: 9 Seasons | F7: British TV Shows, Reality TV
A8: s10 | B8: 9/24/2021 | C8: 2021 | D8: PG-13 | E8: 104 min | F8: Comedies, Dramas
A9: s939 | B9: 05/01/2021 | C9: 2019 | D9: TV-Y7 | E9: 87 min | F9: Children & Family Movies, Comedies, Music & Musicals
A10: s13 | B10: 9/23/2021 | C10: 2021 | D10: TV-MA | E10: 127 min | F10: Dramas, International Movies
A11: s940 | B11: 05/01/2021 | C11: 2013 | D11: TV-Y7 | E11: 76 min | F11: Children & Family Movies, Music & Musicals
A12: s941 | B12: 05/01/2021 | C12: 2014 | D12: TV-Y7 | E12: 76 min | F12: Children & Family Movies, Comedies
A13: s942 | B13: 05/01/2021 | C13: 2013 | D13: TV-Y7 | E13: 71 min | F13: Children & Family Movies, Comedies
... A8791: s8786 | B8791: 06/07/2018 | C8791: 2016 | D8791: TV-Y7 | E8791: 1 Season | F8791: Kids' TV

Sheet netflixPart1
A1: show_id | B1: type | C1: title | D1: director | E1: country | F1: {=_xlfn._xlws.FILTER(netflixPart2!A1:F1,ISNA(_xlfn.XMATCH(netflixPart2!A1:F1,A1:E1)))} -> date_added | G1: release_year | H1: rating | I1: duration | J1: listed_in | K1: duplication
A2: s1 | B2: Movie | C2: Dick Johnson Is Dead | D2: Kirsten Johnson | E2: United States | F2: {=IFERROR(_xlfn.XLOOKUP($A2,netflixPart2!$A:$A,_xlfn.CHOOSECOLS(netflixPart2!$A:$F,_xlfn.XMATCH(netflixPart1!F$1,netflixPart2!$A$1:$F$1))),"Missing")} -> 9/25/2021 | G2: {=DATE(IFERROR(_xlfn.XLOOKUP($A2,netflixPart2!$A:$A,_xlfn.CHOOSECOLS(netflixPart2!$A:$F,_xlfn.XMATCH(netflixPart1!G$1,netflixPart2!$A$1:$F$1))),"Missing"),1,1)} -> 43831 | H2: {=IFERROR(_xlfn.XLOOKUP($A2,netflixPart2!$A:$A,_xlfn.CHOOSECOLS(netflixPart2!$A:$F,_xlfn.XMATCH(netflixPart1!H$1,netflixPart2!$A$1:$F$1))),"Missing")} -> PG-13 | I2: {=IFERROR(_xlfn.XLOOKUP($A2,netflixPart2!$A:$A,_xlfn.CHOOSECOLS(netflixPart2!$A:$F,_xlfn.XMATCH(netflixPart1!I$1,netflixPart2!$A$1:$F$1))),"Missing")} -> 90 min | J2: {=IFERROR(_xlfn.XLOOKUP($A2,netflixPart2!$A:$A,_xlfn.CHOOSECOLS(netflixPart2!$A:$F,_xlfn.XMATCH(netflixPart1!J$1,netflixPart2!$A$1:$F$1))),"Missing")} -> Documentaries
A3: s3 | B3: TV Show | C3: Ganglands | D3: Julien Leclercq | E3: France | F3: {=IFERROR(_xlfn.XLOOKUP($A3,netflixPart2!$A:$A,_xlfn.CHOOSECOLS(netflixPart2!$A:$F,_xlfn.XMATCH(netflixPart1!F$1,netflixPart2!$A$1:$F$1))),"Missing")} -> 9/24/2021 | G3: {=DATE(IFERROR(_xlfn.XLOOKUP($A3,netflixPart2!$A:$A,_xlfn.CHOOSECOLS(netflixPart2!$A:$F,_xlfn.XMATCH(netflixPart1!G$1,netflixPart2!$A$1:$F$1))),"Missing"),1,1)} -> 44197 | H3: {=IFERROR(_xlfn.XLOOKUP($A3,netflixPart2!$A:$A,_xlfn.CHOOSECOLS(netflixPart2!$A:$F,_xlfn.XMATCH(netflixPart1!H$1,netflixPart2!$A$1:$F$1))),"Missing")} -> TV-MA | I3: {=IFERROR(_xlfn.XLOOKUP($A3,netflixPart2!$A:$A,_xlfn.CHOOSECOLS(netflixPart2!$A:$F,_xlfn.XMATCH(netflixPart1!I$1,netflixPart2!$A$1:$F$1))),"Missing")} -> 1 Season | J3: {=IFERROR(_xlfn.XLOOKUP($A3,netflixPart2!$A:$A,_xlfn.CHOOSECOLS(netflixPart2!$A:$F,_xlfn.XMATCH(netflixPart1!J$1,netflixPart2!$A$1:$F$1))),"Missing")} -> Crime TV Shows, International TV Shows, TV Action & Adventure
A4: s6 | B4: TV Show | C4: Midnight Mass | D4: Mike Flanagan | E4: United States | F4: {=IFERROR(_xlfn.XLOOKUP($A4,netflixPart2!$A:$A,_xlfn.CHOOSECOLS(netflixPart2!$A:$F,_xlfn.XMATCH(netflixPart1!F$1,netflixPart2!$A$1:$F$1))),"Missing")} -> 9/24/2021 | G4: {=DATE(IFERROR(_xlfn.XLOOKUP($A4,netflixPart2!$A:$A,_xlfn.CHOOSECOLS(netflixPart2!$A:$F,_xlfn.XMATCH(netflixPart1!G$1,netflixPart2!$A$1:$F$1))),"Missing"),1,1)} -> 44197 | H4: {=IFERROR(_xlfn.XLOOKUP($A4,netflixPart2!$A:$A,_xlfn.CHOOSECOLS(netflixPart2!$A:$F,_xlfn.XMATCH(netflixPart1!H$1,netflixPart2!$A$1:$F$1))),"Missing")} -> TV-MA | I4: {=IFERROR(_xlfn.XLOOKUP($A4,netflixPart2!$A:$A,_xlfn.CHOOSECOLS(netflixPart2!$A:$F,_xlfn.XMATCH(netflixPart1!I$1,netflixPart2!$A$1:$F$1))),"Missing")} -> 1 Season | J4: {=IFERROR(_xlfn.XLOOKUP($A4,netflixPart2!$A:$A,_xlfn.CHOOSECOLS(netflixPart2!$A:$F,_xlfn.XMATCH(netflixPart1!J$1,netflixPart2!$A$1:$F$1))),"Missing")} -> TV Dramas, TV Horror, TV Mysteries
A5: s14 | B5: Movie | C5: Confessions of an Invisible Girl | D5: Bruno Garotti | E5: Brazil | F5: {=IFERROR(_xlfn.XLOOKUP($A5,netflixPart2!$A:$A,_xlfn.CHOOSECOLS(netflixPart2!$A:$F,_xlfn.XMATCH(netflixPart1!F$1,netflixPart2!$A$1:$F$1))),"Missing")} -> 9/22/2021 | G5: {=DATE(IFERROR(_xlfn.XLOOKUP($A5,netflixPart2!$A:$A,_xlfn.CHOOSECOLS(netflixPart2!$A:$F,_xlfn.XMATCH(netflixPart1!G$1,netflixPart2!$A$1:$F$1))),"Missing"),1,1)} -> 44197 | H5: {=IFERROR(_xlfn.XLOOKUP($A5,netflixPart2!$A:$A,_xlfn.CHOOSECOLS(netflixPart2!$A:$F,_xlfn.XMATCH(netflixPart1!H$1,netflixPart2!$A$1:$F$1))),"Missing")} -> TV-PG | I5: {=IFERROR(_xlfn.XLOOKUP($A5,netflixPart2!$A:$A,_xlfn.CHOOSECOLS(netflixPart2!$A:$F,_xlfn.XMATCH(netflixPart1!I$1,netflixPart2!$A$1:$F$1))),"Missing")} -> 91 min | J5: {=IFERROR(_xlfn.XLOOKUP($A5,netflixPart2!$A:$A,_xlfn.CHOOSECOLS(netflixPart2!$A:$F,_xlfn.XMATCH(netflixPart1!J$1,netflixPart2!$A$1:$F$1))),"Missing")} -> Children & Family Movies, Comedies
A6: s8 | B6: Movie | C6: Sankofa | D6: Haile Gerima | E6: United States | F6: {=IFERROR(_xlfn.XLOOKUP($A6,netflixPart2!$A:$A,_xlfn.CHOOSECOLS(netflixPart2!$A:$F,_xlfn.XMATCH(netflixPart1!F$1,netflixPart2!$A$1:$F$1))),"Missing")} -> 9/24/2021 | G6: {=DATE(IFERROR(_xlfn.XLOOKUP($A6,netflixPart2!$A:$A,_xlfn.CHOOSECOLS(netflixPart2!$A:$F,_xlfn.XMATCH(netflixPart1!G$1,netflixPart2!$A$1:$F$1))),"Missing"),1,1)} -> 33970 | H6: {=IFERROR(_xlfn.XLOOKUP($A6,netflixPart2!$A:$A,_xlfn.CHOOSECOLS(netflixPart2!$A:$F,_xlfn.XMATCH(netflixPart1!H$1,netflixPart2!$A$1:$F$1))),"Missing")} -> TV-MA | I6: {=IFERROR(_xlfn.XLOOKUP($A6,netflixPart2!$A:$A,_xlfn.CHOOSECOLS(netflixPart2!$A:$F,_xlfn.XMATCH(netflixPart1!I$1,netflixPart2!$A$1:$F$1))),"Missing")} -> 125 min | J6: {=IFERROR(_xlfn.XLOOKUP($A6,netflixPart2!$A:$A,_xlfn.CHOOSECOLS(netflixPart2!$A:$F,_xlfn.XMATCH(netflixPart1!J$1,netflixPart2!$A$1:$F$1))),"Missing")} -> Dramas, Independent Movies, International Movies
A7: s9 | B7: TV Show | C7: The Great British Baking Show | D7: Andy Devonshire | E7: United Kingdom | F7: {=IFERROR(_xlfn.XLOOKUP($A7,netflixPart2!$A:$A,_xlfn.CHOOSECOLS(netflixPart2!$A:$F,_xlfn.XMATCH(netflixPart1!F$1,netflixPart2!$A$1:$F$1))),"Missing")} -> 9/24/2021 | G7: {=DATE(IFERROR(_xlfn.XLOOKUP($A7,netflixPart2!$A:$A,_xlfn.CHOOSECOLS(netflixPart2!$A:$F,_xlfn.XMATCH(netflixPart1!G$1,netflixPart2!$A$1:$F$1))),"Missing"),1,1)} -> 44197 | H7: {=IFERROR(_xlfn.XLOOKUP($A7,netflixPart2!$A:$A,_xlfn.CHOOSECOLS(netflixPart2!$A:$F,_xlfn.XMATCH(netflixPart1!H$1,netflixPart2!$A$1:$F$1))),"Missing")} -> TV-14 | I7: {=IFERROR(_xlfn.XLOOKUP($A7,netflixPart2!$A:$A,_xlfn.CHOOSECOLS(netflixPart2!$A:$F,_xlfn.XMATCH(netflixPart1!I$1,netflixPart2!$A$1:$F$1))),"Missing")} -> 9 Seasons | J7: {=IFERROR(_xlfn.XLOOKUP($A7,netflixPart2!$A:$A,_xlfn.CHOOSECOLS(netflixPart2!$A:$F,_xlfn.XMATCH(netflixPart1!J$1,netflixPart2!$A$1:$F$1))),"Missing")} -> British TV Shows, Reality TV
A8: s10 | B8: Movie | C8: The Starling | D8: Theodore Melfi | E8: United States | F8: {=IFERROR(_xlfn.XLOOKUP($A8,netflixPart2!$A:$A,_xlfn.CHOOSECOLS(netflixPart2!$A:$F,_xlfn.XMATCH(netflixPart1!F$1,netflixPart2!$A$1:$F$1))),"Missing")} -> 9/24/2021 | G8: {=DATE(IFERROR(_xlfn.XLOOKUP($A8,netflixPart2!$A:$A,_xlfn.CHOOSECOLS(netflixPart2!$A:$F,_xlfn.XMATCH(netflixPart1!G$1,netflixPart2!$A$1:$F$1))),"Missing"),1,1)} -> 44197 | H8: {=IFERROR(_xlfn.XLOOKUP($A8,netflixPart2!$A:$A,_xlfn.CHOOSECOLS(netflixPart2!$A:$F,_xlfn.XMATCH(netflixPart1!H$1,netflixPart2!$A$1:$F$1))),"Missing")} -> PG-13 | I8: {=IFERROR(_xlfn.XLOOKUP($A8,netflixPart2!$A:$A,_xlfn.CHOOSECOLS(netflixPart2!$A:$F,_xlfn.XMATCH(netflixPart1!I$1,netflixPart2!$A$1:$F$1))),"Missing")} -> 104 min | J8: {=IFERROR(_xlfn.XLOOKUP($A8,netflixPart2!$A:$A,_xlfn.CHOOSECOLS(netflixPart2!$A:$F,_xlfn.XMATCH(netflixPart1!J$1,netflixPart2!$A$1:$F$1))),"Missing")} -> Comedies, Dramas
A9: s939 | B9: Movie | C9: Motu Patlu in the Game of Zones | D9: Suhas Kadav | E9: India | F9: {=IFERROR(_xlfn.XLOOKUP($A9,netflixPart2!$A:$A,_xlfn.CHOOSECOLS(netflixPart2!$A:$F,_xlfn.XMATCH(netflixPart1!F$1,netflixPart2!$A$1:$F$1))),"Missing")} -> 05/01/2021 | G9: {=DATE(IFERROR(_xlfn.XLOOKUP($A9,netflixPart2!$A:$A,_xlfn.CHOOSECOLS(netflixPart2!$A:$F,_xlfn.XMATCH(netflixPart1!G$1,netflixPart2!$A$1:$F$1))),"Missing"),1,1)} -> 43466 | H9: {=IFERROR(_xlfn.XLOOKUP($A9,netflixPart2!$A:$A,_xlfn.CHOOSECOLS(netflixPart2!$A:$F,_xlfn.XMATCH(netflixPart1!H$1,netflixPart2!$A$1:$F$1))),"Missing")} -> TV-Y7 | I9: {=IFERROR(_xlfn.XLOOKUP($A9,netflixPart2!$A:$A,_xlfn.CHOOSECOLS(netflixPart2!$A:$F,_xlfn.XMATCH(netflixPart1!I$1,netflixPart2!$A$1:$F$1))),"Missing")} -> 87 min | J9: {=IFERROR(_xlfn.XLOOKUP($A9,netflixPart2!$A:$A,_xlfn.CHOOSECOLS(netflixPart2!$A:$F,_xlfn.XMATCH(netflixPart1!J$1,netflixPart2!$A$1:$F$1))),"Missing")} -> Children & Family Movies, Comedies, Music & Musicals
A10: s13 | B10: Movie | C10: Je Suis Karl | D10: Christian Schwochow | E10: Germany | F10: {=IFERROR(_xlfn.XLOOKUP($A10,netflixPart2!$A:$A,_xlfn.CHOOSECOLS(netflixPart2!$A:$F,_xlfn.XMATCH(netflixPart1!F$1,netflixPart2!$A$1:$F$1))),"Missing")} -> 9/23/2021 | G10: {=DATE(IFERROR(_xlfn.XLOOKUP($A10,netflixPart2!$A:$A,_xlfn.CHOOSECOLS(netflixPart2!$A:$F,_xlfn.XMATCH(netflixPart1!G$1,netflixPart2!$A$1:$F$1))),"Missing"),1,1)} -> 44197 | H10: {=IFERROR(_xlfn.XLOOKUP($A10,netflixPart2!$A:$A,_xlfn.CHOOSECOLS(netflixPart2!$A:$F,_xlfn.XMATCH(netflixPart1!H$1,netflixPart2!$A$1:$F$1))),"Missing")} -> TV-MA | I10: {=IFERROR(_xlfn.XLOOKUP($A10,netflixPart2!$A:$A,_xlfn.CHOOSECOLS(netflixPart2!$A:$F,_xlfn.XMATCH(netflixPart1!I$1,netflixPart2!$A$1:$F$1))),"Missing")} -> 127 min | J10: {=IFERROR(_xlfn.XLOOKUP($A10,netflixPart2!$A:$A,_xlfn.CHOOSECOLS(netflixPart2!$A:$F,_xlfn.XMATCH(netflixPart1!J$1,netflixPart2!$A$1:$F$1))),"Missing")} -> Dramas, International Movies
A11: s940 | B11: Movie | C11: Motu Patlu in Wonderland | D11: Suhas Kadav | E11: India | F11: {=IFERROR(_xlfn.XLOOKUP($A11,netflixPart2!$A:$A,_xlfn.CHOOSECOLS(netflixPart2!$A:$F,_xlfn.XMATCH(netflixPart1!F$1,netflixPart2!$A$1:$F$1))),"Missing")} -> 05/01/2021 | G11: {=DATE(IFERROR(_xlfn.XLOOKUP($A11,netflixPart2!$A:$A,_xlfn.CHOOSECOLS(netflixPart2!$A:$F,_xlfn.XMATCH(netflixPart1!G$1,netflixPart2!$A$1:$F$1))),"Missing"),1,1)} -> 41275 | H11: {=IFERROR(_xlfn.XLOOKUP($A11,netflixPart2!$A:$A,_xlfn.CHOOSECOLS(netflixPart2!$A:$F,_xlfn.XMATCH(netflixPart1!H$1,netflixPart2!$A$1:$F$1))),"Missing")} -> TV-Y7 | I11: {=IFERROR(_xlfn.XLOOKUP($A11,netflixPart2!$A:$A,_xlfn.CHOOSECOLS(netflixPart2!$A:$F,_xlfn.XMATCH(netflixPart1!I$1,netflixPart2!$A$1:$F$1))),"Missing")} -> 76 min | J11: {=IFERROR(_xlfn.XLOOKUP($A11,netflixPart2!$A:$A,_xlfn.CHOOSECOLS(netflixPart2!$A:$F,_xlfn.XMATCH(netflixPart1!J$1,netflixPart2!$A$1:$F$1))),"Missing")} -> Children & Family Movies, Music & Musicals
A12: s941 | B12: Movie | C12: Motu Patlu: Deep Sea Adventure | D12: Suhas Kadav | E12: India | F12: {=IFERROR(_xlfn.XLOOKUP($A12,netflixPart2!$A:$A,_xlfn.CHOOSECOLS(netflixPart2!$A:$F,_xlfn.XMATCH(netflixPart1!F$1,netflixPart2!$A$1:$F$1))),"Missing")} -> 05/01/2021 | G12: {=DATE(IFERROR(_xlfn.XLOOKUP($A12,netflixPart2!$A:$A,_xlfn.CHOOSECOLS(netflixPart2!$A:$F,_xlfn.XMATCH(netflixPart1!G$1,netflixPart2!$A$1:$F$1))),"Missing"),1,1)} -> 41640 | H12: {=IFERROR(_xlfn.XLOOKUP($A12,netflixPart2!$A:$A,_xlfn.CHOOSECOLS(netflixPart2!$A:$F,_xlfn.XMATCH(netflixPart1!H$1,netflixPart2!$A$1:$F$1))),"Missing")} -> TV-Y7 | I12: {=IFERROR(_xlfn.XLOOKUP($A12,netflixPart2!$A:$A,_xlfn.CHOOSECOLS(netflixPart2!$A:$F,_xlfn.XMATCH(netflixPart1!I$1,netflixPart2!$A$1:$F$1))),"Missing")} -> 76 min | J12: {=IFERROR(_xlfn.XLOOKUP($A12,netflixPart2!$A:$A,_xlfn.CHOOSECOLS(netflixPart2!$A:$F,_xlfn.XMATCH(netflixPart1!J$1,netflixPart2!$A$1:$F$1))),"Missing")} -> Children & Family Movies, Comedies
A13: s942 | B13: Movie | C13: Motu Patlu: Mission Moon | D13: Suhas Kadav | E13: India | F13: {=IFERROR(_xlfn.XLOOKUP($A13,netflixPart2!$A:$A,_xlfn.CHOOSECOLS(netflixPart2!$A:$F,_xlfn.XMATCH(netflixPart1!F$1,netflixPart2!$A$1:$F$1))),"Missing")} -> 05/01/2021 | G13: {=DATE(IFERROR(_xlfn.XLOOKUP($A13,netflixPart2!$A:$A,_xlfn.CHOOSECOLS(netflixPart2!$A:$F,_xlfn.XMATCH(netflixPart1!G$1,netflixPart2!$A$1:$F$1))),"Missing"),1,1)} -> 41275 | H13: {=IFERROR(_xlfn.XLOOKUP($A13,netflixPart2!$A:$A,_xlfn.CHOOSECOLS(netflixPart2!$A:$F,_xlfn.XMATCH(netflixPart1!H$1,netflixPart2!$A$1:$F$1))),"Missing")} -> TV-Y7 | I13: {=IFERROR(_xlfn.XLOOKUP($A13,netflixPart2!$A:$A,_xlfn.CHOOSECOLS(netflixPart2!$A:$F,_xlfn.XMATCH(netflixPart1!I$1,netflixPart2!$A$1:$F$1))),"Missing")} -> 71 min | J13: {=IFERROR(_xlfn.XLOOKUP($A13,netflixPart2!$A:$A,_xlfn.CHOOSECOLS(netflixPart2!$A:$F,_xlfn.XMATCH(netflixPart1!J$1,netflixPart2!$A$1:$F$1))),"Missing")} -> Children & Family Movies, Comedies
A14: s852 | B14: Movie | C14: 99 Songs (Tamil) | D14: Not Given | E14: Pakistan | F14: {=IFERROR(_xlfn.XLOOKUP($A14,netflixPart2!$A:$A,_xlfn.CHOOSECOLS(netflixPart2!$A:$F,_xlfn.XMATCH(netflixPart1!F$1,netflixPart2!$A$1:$F$1))),"Missing")} -> 5/21/2021 | G14: {=DATE(IFERROR(_xlfn.XLOOKUP($A14,netflixPart2!$A:$A,_xlfn.CHOOSECOLS(netflixPart2!$A:$F,_xlfn.XMATCH(netflixPart1!G$1,netflixPart2!$A$1:$F$1))),"Missing"),1,1)} -> 44197 | H14: {=IFERROR(_xlfn.XLOOKUP($A14,netflixPart2!$A:$A,_xlfn.CHOOSECOLS(netflixPart2!$A:$F,_xlfn.XMATCH(netflixPart1!H$1,netflixPart2!$A$1:$F$1))),"Missing")} -> TV-14 | I14: {=IFERROR(_xlfn.XLOOKUP($A14,netflixPart2!$A:$A,_xlfn.CHOOSECOLS(netflixPart2!$A:$F,_xlfn.XMATCH(netflixPart1!I$1,netflixPart2!$A$1:$F$1))),"Missing")} -> 131 min | J14: {=IFERROR(_xlfn.XLOOKUP($A14,netflixPart2!$A:$A,_xlfn.CHOOSECOLS(netflixPart2!$A:$F,_xlfn.XMATCH(netflixPart1!J$1,netflixPart2!$A$1:$F$1))),"Missing")} -> Dramas, International Movies, Music & Musicals
A15: s471 | B15: Movie | C15: Bridgerton - The Afterparty | D15: Krysia Plonka, Kristian Mercado | E15: United States | F15: {=IFERROR(_xlfn.XLOOKUP($A15,netflixPart2!$A:$A,_xlfn.CHOOSECOLS(netflixPart2!$A:$F,_xlfn.XMATCH(netflixPart1!F$1,netflixPart2!$A$1:$F$1))),"Missing")} -> 7/13/2021 | G15: {=DATE(IFERROR(_xlfn.XLOOKUP($A15,netflixPart2!$A:$A,_xlfn.CHOOSECOLS(netflixPart2!$A:$F,_xlfn.XMATCH(netflixPart1!G$1,netflixPart2!$A$1:$F$1))),"Missing"),1,1)} -> 44197 | H15: {=IFERROR(_xlfn.XLOOKUP($A15,netflixPart2!$A:$A,_xlfn.CHOOSECOLS(netflixPart2!$A:$F,_xlfn.XMATCH(netflixPart1!H$1,netflixPart2!$A$1:$F$1))),"Missing")} -> TV-14 | I15: {=IFERROR(_xlfn.XLOOKUP($A15,netflixPart2!$A:$A,_xlfn.CHOOSECOLS(netflixPart2!$A:$F,_xlfn.XMATCH(netflixPart1!I$1,netflixPart2!$A$1:$F$1))),"Missing")} -> 39 min | J15: {=IFERROR(_xlfn.XLOOKUP($A15,netflixPart2!$A:$A,_xlfn.CHOOSECOLS(netflixPart2!$A:$F,_xlfn.XMATCH(netflixPart1!J$1,netflixPart2!$A$1:$F$1))),"Missing")} -> Movies | P15: =DATE(1900,1,1) -> 1
A16: s730 | B16: Movie | C16: Bling Empire - The Afterparty | D16: Krysia Plonka, Kristian Mercado | E16: United States | F16: {=IFERROR(_xlfn.XLOOKUP($A16,netflixPart2!$A:$A,_xlfn.CHOOSECOLS(netflixPart2!$A:$F,_xlfn.XMATCH(netflixPart1!F$1,netflixPart2!$A$1:$F$1))),"Missing")} -> 06/12/2021 | G16: {=DATE(IFERROR(_xlfn.XLOOKUP($A16,netflixPart2!$A:$A,_xlfn.CHOOSECOLS(netflixPart2!$A:$F,_xlfn.XMATCH(netflixPart1!G$1,netflixPart2!$A$1:$F$1))),"Missing"),1,1)} -> 44197 | H16: {=IFERROR(_xlfn.XLOOKUP($A16,netflixPart2!$A:$A,_xlfn.CHOOSECOLS(netflixPart2!$A:$F,_xlfn.XMATCH(netflixPart1!H$1,netflixPart2!$A$1:$F$1))),"Missing")} -> TV-MA | I16: {=IFERROR(_xlfn.XLOOKUP($A16,netflixPart2!$A:$A,_xlfn.CHOOSECOLS(netflixPart2!$A:$F,_xlfn.XMATCH(netflixPart1!I$1,netflixPart2!$A$1:$F$1))),"Missing")} -> 36 min | J16: {=IFERROR(_xlfn.XLOOKUP($A16,netflixPart2!$A:$A,_xlfn.CHOOSECOLS(netflixPart2!$A:$F,_xlfn.XMATCH(netflixPart1!J$1,netflixPart2!$A$1:$F$1))),"Missing")} -> Movies
A17: s731 | B17: Movie | C17: Cobra Kai - The Afterparty | D17: Krysia Plonka, Kristian Mercado | E17: United States | F17: {=IFERROR(_xlfn.XLOOKUP($A17,netflixPart2!$A:$A,_xlfn.CHOOSECOLS(netflixPart2!$A:$F,_xlfn.XMATCH(netflixPart1!F$1,netflixPart2!$A$1:$F$1))),"Missing")} -> 06/12/2021 | G17: {=DATE(IFERROR(_xlfn.XLOOKUP($A17,netflixPart2!$A:$A,_xlfn.CHOOSECOLS(netflixPart2!$A:$F,_xlfn.XMATCH(netflixPart1!G$1,netflixPart2!$A$1:$F$1))),"Missing"),1,1)} -> 44197 | H17: {=IFERROR(_xlfn.XLOOKUP($A17,netflixPart2!$A:$A,_xlfn.CHOOSECOLS(netflixPart2!$A:$F,_xlfn.XMATCH(netflixPart1!H$1,netflixPart2!$A$1:$F$1))),"Missing")} -> TV-MA | I17: {=IFERROR(_xlfn.XLOOKUP($A17,netflixPart2!$A:$A,_xlfn.CHOOSECOLS(netflixPart2!$A:$F,_xlfn.XMATCH(netflixPart1!I$1,netflixPart2!$A$1:$F$1))),"Missing")} -> 34 min | J17: {=IFERROR(_xlfn.XLOOKUP($A17,netflixPart2!$A:$A,_xlfn.CHOOSECOLS(netflixPart2!$A:$F,_xlfn.XMATCH(netflixPart1!J$1,netflixPart2!$A$1:$F$1))),"Missing")} -> Movies
A18: s913 | B18: Movie | C18: The Circle - The Afterparty | D18: Krysia Plonka, Kristian Mercado | E18: United States | F18: {=IFERROR(_xlfn.XLOOKUP($A18,netflixPart2!$A:$A,_xlfn.CHOOSECOLS(netflixPart2!$A:$F,_xlfn.XMATCH(netflixPart1!F$1,netflixPart2!$A$1:$F$1))),"Missing")} -> 05/07/2021 | G18: {=DATE(IFERROR(_xlfn.XLOOKUP($A18,netflixPart2!$A:$A,_xlfn.CHOOSECOLS(netflixPart2!$A:$F,_xlfn.XMATCH(netflixPart1!G$1,netflixPart2!$A$1:$F$1))),"Missing"),1,1)} -> 44197 | H18: {=IFERROR(_xlfn.XLOOKUP($A18,netflixPart2!$A:$A,_xlfn.CHOOSECOLS(netflixPart2!$A:$F,_xlfn.XMATCH(netflixPart1!H$1,netflixPart2!$A$1:$F$1))),"Missing")} -> TV-14 | I18: {=IFERROR(_xlfn.XLOOKUP($A18,netflixPart2!$A:$A,_xlfn.CHOOSECOLS(netflixPart2!$A:$F,_xlfn.XMATCH(netflixPart1!I$1,netflixPart2!$A$1:$F$1))),"Missing")} -> 35 min | J18: {=IFERROR(_xlfn.XLOOKUP($A18,netflixPart2!$A:$A,_xlfn.CHOOSECOLS(netflixPart2!$A:$F,_xlfn.XMATCH(netflixPart1!J$1,netflixPart2!$A$1:$F$1))),"Missing")} -> Comedies
A19: s4 | B19: TV Show | C19: Jailbirds New Orleans | D19: Not Given | E19: Pakistan | F19: {=IFERROR(_xlfn.XLOOKUP($A19,netflixPart2!$A:$A,_xlfn.CHOOSECOLS(netflixPart2!$A:$F,_xlfn.XMATCH(netflixPart1!F$1,netflixPart2!$A$1:$F$1))),"Missing")} -> 9/24/2021 | G19: {=DATE(IFERROR(_xlfn.XLOOKUP($A19,netflixPart2!$A:$A,_xlfn.CHOOSECOLS(netflixPart2!$A:$F,_xlfn.XMATCH(netflixPart1!G$1,netflixPart2!$A$1:$F$1))),"Missing"),1,1)} -> 44197 | H19: {=IFERROR(_xlfn.XLOOKUP($A19,netflixPart2!$A:$A,_xlfn.CHOOSECOLS(netflixPart2!$A:$F,_xlfn.XMATCH(netflixPart1!H$1,netflixPart2!$A$1:$F$1))),"Missing")} -> TV-MA | I19: {=IFERROR(_xlfn.XLOOKUP($A19,netflixPart2!$A:$A,_xlfn.CHOOSECOLS(netflixPart2!$A:$F,_xlfn.XMATCH(netflixPart1!I$1,netflixPart2!$A$1:$F$1))),"Missing")} -> 1 Season | J19: {=IFERROR(_xlfn.XLOOKUP($A19,netflixPart2!$A:$A,_xlfn.CHOOSECOLS(netflixPart2!$A:$F,_xlfn.XMATCH(netflixPart1!J$1,netflixPart2!$A$1:$F$1))),"Missing")} -> Docuseries, Reality TV
A20: s15 | B20: TV Show | C20: Crime Stories: India Detectives | D20: Not Given | E20: Pakistan | F20: {=IFERROR(_xlfn.XLOOKUP($A20,netflixPart2!$A:$A,_xlfn.CHOOSECOLS(netflixPart2!$A:$F,_xlfn.XMATCH(netflixPart1!F$1,netflixPart2!$A$1:$F$1))),"Missing")} -> 9/22/2021 | G20: {=DATE(IFERROR(_xlfn.XLOOKUP($A20,netflixPart2!$A:$A,_xlfn.CHOOSECOLS(netflixPart2!$A:$F,_xlfn.XMATCH(netflixPart1!G$1,netflixPart2!$A$1:$F$1))),"Missing"),1,1)} -> 44197 | H20: {=IFERROR(_xlfn.XLOOKUP($A20,netflixPart2!$A:$A,_xlfn.CHOOSECOLS(netflixPart2!$A:$F,_xlfn.XMATCH(netflixPart1!H$1,netflixPart2!$A$1:$F$1))),"Missing")} -> TV-MA | I20: {=IFERROR(_xlfn.XLOOKUP($A20,netflixPart2!$A:$A,_xlfn.CHOOSECOLS(netflixPart2!$A:$F,_xlfn.XMATCH(netflixPart1!I$1,netflixPart2!$A$1:$F$1))),"Missing")} -> 1 Season | J20: {=IFERROR(_xlfn.XLOOKUP($A20,netflixPart2!$A:$A,_xlfn.CHOOSECOLS(netflixPart2!$A:$F,_xlfn.XMATCH(netflixPart1!J$1,netflixPart2!$A$1:$F$1))),"Missing")} -> British TV Shows, Crime TV Shows, Docuseries
A21: s3232 | B21: Movie | C21: True: Winter Wishes | D21: Mark Thornton, Todd Kauffman | E21: United States | F21: {=IFERROR(_xlfn.XLOOKUP($A21,netflixPart2!$A:$A,_xlfn.CHOOSECOLS(netflixPart2!$A:$F,_xlfn.XMATCH(netflixPart1!F$1,netflixPart2!$A$1:$F$1))),"Missing")} -> 11/26/2019 | G21: {=DATE(IFERROR(_xlfn.XLOOKUP($A21,netflixPart2!$A:$A,_xlfn.CHOOSECOLS(netflixPart2!$A:$F,_xlfn.XMATCH(netflixPart1!G$1,netflixPart2!$A$1:$F$1))),"Missing"),1,1)} -> 43466 | H21: {=IFERROR(_xlfn.XLOOKUP($A21,netflixPart2!$A:$A,_xlfn.CHOOSECOLS(netflixPart2!$A:$F,_xlfn.XMATCH(netflixPart1!H$1,netflixPart2!$A$1:$F$1))),"Missing")} -> TV-Y | I21: {=IFERROR(_xlfn.XLOOKUP($A21,netflixPart2!$A:$A,_xlfn.CHOOSECOLS(netflixPart2!$A:$F,_xlfn.XMATCH(netflixPart1!I$1,netflixPart2!$A$1:$F$1))),"Missing")} -> 46 min | J21: {=IFERROR(_xlfn.XLOOKUP($A21,netflixPart2!$A:$A,_xlfn.CHOOSECOLS(netflixPart2!$A:$F,_xlfn.XMATCH(netflixPart1!J$1,netflixPart2!$A$1:$F$1))),"Missing")} -> Children & Family Movies
A22: s4832 | B22: TV Show | C22: True: Magical Friends | D22: Mark Thornton, Todd Kauffman | E22: United States | F22: {=IFERROR(_xlfn.XLOOKUP($A22,netflixPart2!$A:$A,_xlfn.CHOOSECOLS(netflixPart2!$A:$F,_xlfn.XMATCH(netflixPart1!F$1,netflixPart2!$A$1:$F$1))),"Missing")} -> 6/15/2018 | G22: {=DATE(IFERROR(_xlfn.XLOOKUP($A22,netflixPart2!$A:$A,_xlfn.CHOOSECOLS(netflixPart2!$A:$F,_xlfn.XMATCH(netflixPart1!G$1,netflixPart2!$A$1:$F$1))),"Missing"),1,1)} -> 43101 | H22: {=IFERROR(_xlfn.XLOOKUP($A22,netflixPart2!$A:$A,_xlfn.CHOOSECOLS(netflixPart2!$A:$F,_xlfn.XMATCH(netflixPart1!H$1,netflixPart2!$A$1:$F$1))),"Missing")} -> TV-Y | I22: {=IFERROR(_xlfn.XLOOKUP($A22,netflixPart2!$A:$A,_xlfn.CHOOSECOLS(netflixPart2!$A:$F,_xlfn.XMATCH(netflixPart1!I$1,netflixPart2!$A$1:$F$1))),"Missing")} -> 1 Season | J22: {=IFERROR(_xlfn.XLOOKUP($A22,netflixPart2!$A:$A,_xlfn.CHOOSECOLS(netflixPart2!$A:$F,_xlfn.XMATCH(netflixPart1!J$1,netflixPart2!$A$1:$F$1))),"Missing")} -> Kids' TV
A23: s4833 | B23: TV Show | C23: True: Wonderful Wishes | D23: Mark Thornton, Todd Kauffman | E23: United States | F23: {=IFERROR(_xlfn.XLOOKUP($A23,netflixPart2!$A:$A,_xlfn.CHOOSECOLS(netflixPart2!$A:$F,_xlfn.XMATCH(netflixPart1!F$1,netflixPart2!$A$1:$F$1))),"Missing")} -> 6/15/2018 | G23: {=DATE(IFERROR(_xlfn.XLOOKUP($A23,netflixPart2!$A:$A,_xlfn.CHOOSECOLS(netflixPart2!$A:$F,_xlfn.XMATCH(netflixPart1!G$1,netflixPart2!$A$1:$F$1))),"Missing"),1,1)} -> 43101 | H23: {=IFERROR(_xlfn.XLOOKUP($A23,netflixPart2!$A:$A,_xlfn.CHOOSECOLS(netflixPart2!$A:$F,_xlfn.XMATCH(netflixPart1!H$1,netflixPart2!$A$1:$F$1))),"Missing")} -> TV-Y | I23: {=IFERROR(_xlfn.XLOOKUP($A23,netflixPart2!$A:$A,_xlfn.CHOOSECOLS(netflixPart2!$A:$F,_xlfn.XMATCH(netflixPart1!I$1,netflixPart2!$A$1:$F$1))),"Missing")} -> 1 Season | J23: {=IFERROR(_xlfn.XLOOKUP($A23,netflixPart2!$A:$A,_xlfn.CHOOSECOLS(netflixPart2!$A:$F,_xlfn.XMATCH(netflixPart1!J$1,netflixPart2!$A$1:$F$1))),"Missing")} -> Kids' TV
A24: s4857 | B24: TV Show | C24: Dance & Sing with True | D24: Mark Thornton, Todd Kauffman | E24: United States | F24: {=IFERROR(_xlfn.XLOOKUP($A24,netflixPart2!$A:$A,_xlfn.CHOOSECOLS(netflixPart2!$A:$F,_xlfn.XMATCH(netflixPart1!F$1,netflixPart2!$A$1:$F$1))),"Missing")} -> 5/18/2018 | G24: {=DATE(IFERROR(_xlfn.XLOOKUP($A24,netflixPart2!$A:$A,_xlfn.CHOOSECOLS(netflixPart2!$A:$F,_xlfn.XMATCH(netflixPart1!G$1,netflixPart2!$A$1:$F$1))),"Missing"),1,1)} -> 43101 | H24: {=IFERROR(_xlfn.XLOOKUP($A24,netflixPart2!$A:$A,_xlfn.CHOOSECOLS(netflixPart2!$A:$F,_xlfn.XMATCH(netflixPart1!H$1,netflixPart2!$A$1:$F$1))),"Missing")} -> TV-Y | I24: {=IFERROR(_xlfn.XLOOKUP($A24,netflixPart2!$A:$A,_xlfn.CHOOSECOLS(netflixPart2!$A:$F,_xlfn.XMATCH(netflixPart1!I$1,netflixPart2!$A$1:$F$1))),"Missing")} -> 1 Season | J24: {=IFERROR(_xlfn.XLOOKUP($A24,netflixPart2!$A:$A,_xlfn.CHOOSECOLS(netflixPart2!$A:$F,_xlfn.XMATCH(netflixPart1!J$1,netflixPart2!$A$1:$F$1))),"Missing")} -> Kids' TV
A25: s7 | B25: Movie | C25: My Little Pony: A New Generation | D25: Robert Cullen, José Luis Ucha | E25: Not Given | F25: {=IFERROR(_xlfn.XLOOKUP($A25,netflixPart2!$A:$A,_xlfn.CHOOSECOLS(netflixPart2!$A:$F,_xlfn.XMATCH(netflixPart1!F$1,netflixPart2!$A$1:$F$1))),"Missing")} -> 9/24/2021 | G25: {=DATE(IFERROR(_xlfn.XLOOKUP($A25,netflixPart2!$A:$A,_xlfn.CHOOSECOLS(netflixPart2!$A:$F,_xlfn.XMATCH(netflixPart1!G$1,netflixPart2!$A$1:$F$1))),"Missing"),1,1)} -> 44197 | H25: {=IFERROR(_xlfn.XLOOKUP($A25,netflixPart2!$A:$A,_xlfn.CHOOSECOLS(netflixPart2!$A:$F,_xlfn.XMATCH(netflixPart1!H$1,netflixPart2!$A$1:$F$1))),"Missing")} -> PG | I25: {=IFERROR(_xlfn.XLOOKUP($A25,netflixPart2!$A:$A,_xlfn.CHOOSECOLS(netflixPart2!$A:$F,_xlfn.XMATCH(netflixPart1!I$1,netflixPart2!$A$1:$F$1))),"Missing")} -> 91 min | J25: {=IFERROR(_xlfn.XLOOKUP($A25,netflixPart2!$A:$A,_xlfn.CHOOSECOLS(netflixPart2!$A:$F,_xlfn.XMATCH(netflixPart1!J$1,netflixPart2!$A$1:$F$1))),"Missing")} -> Children & Family Movies
A26: s12 | B26: TV Show | C26: Bangkok Breaking | D26: Kongkiat Komesiri | E26: Not Given | F26: {=IFERROR(_xlfn.XLOOKUP($A26,netflixPart2!$A:$A,_xlfn.CHOOSECOLS(netflixPart2!$A:$F,_xlfn.XMATCH(netflixPart1!F$1,netflixPart2!$A$1:$F$1))),"Missing")} -> 9/23/2021 | G26: {=DATE(IFERROR(_xlfn.XLOOKUP($A26,netflixPart2!$A:$A,_xlfn.CHOOSECOLS(netflixPart2!$A:$F,_xlfn.XMATCH(netflixPart1!G$1,netflixPart2!$A$1:$F$1))),"Missing"),1,1)} -> 44197 | H26: {=IFERROR(_xlfn.XLOOKUP($A26,netflixPart2!$A:$A,_xlfn.CHOOSECOLS(netflixPart2!$A:$F,_xlfn.XMATCH(netflixPart1!H$1,netflixPart2!$A$1:$F$1))),"Missing")} -> TV-MA | I26: {=IFERROR(_xlfn.XLOOKUP($A26,netflixPart2!$A:$A,_xlfn.CHOOSECOLS(netflixPart2!$A:$F,_xlfn.XMATCH(netflixPart1!I$1,netflixPart2!$A$1:$F$1))),"Missing")} -> 1 Season | J26: {=IFERROR(_xlfn.XLOOKUP($A26,netflixPart2!$A:$A,_xlfn.CHOOSECOLS(netflixPart2!$A:$F,_xlfn.XMATCH(netflixPart1!J$1,netflixPart2!$A$1:$F$1))),"Missing")} -> Crime TV Shows, International TV Shows, TV Action & Adventure
A27: s17 | B27: Movie | C27: Europe's Most Dangerous Man: Otto Skorzeny in Spain | D27: Pedro de Echave García, Pablo Azorín Williams | E27: Not Given | F27: {=IFERROR(_xlfn.XLOOKUP($A27,netflixPart2!$A:$A,_xlfn.CHOOSECOLS(netflixPart2!$A:$F,_xlfn.XMATCH(netflixPart1!F$1,netflixPart2!$A$1:$F$1))),"Missing")} -> 9/22/2021 | G27: {=DATE(IFERROR(_xlfn.XLOOKUP($A27,netflixPart2!$A:$A,_xlfn.CHOOSECOLS(netflixPart2!$A:$F,_xlfn.XMATCH(netflixPart1!G$1,netflixPart2!$A$1:$F$1))),"Missing"),1,1)} -> 43831 | H27: {=IFERROR(_xlfn.XLOOKUP($A27,netflixPart2!$A:$A,_xlfn.CHOOSECOLS(netflixPart2!$A:$F,_xlfn.XMATCH(netflixPart1!H$1,netflixPart2!$A$1:$F$1))),"Missing")} -> TV-MA | I27: {=IFERROR(_xlfn.XLOOKUP($A27,netflixPart2!$A:$A,_xlfn.CHOOSECOLS(netflixPart2!$A:$F,_xlfn.XMATCH(netflixPart1!I$1,netflixPart2!$A$1:$F$1))),"Missing")} -> 67 min | J27: {=IFERROR(_xlfn.XLOOKUP($A27,netflixPart2!$A:$A,_xlfn.CHOOSECOLS(netflixPart2!$A:$F,_xlfn.XMATCH(netflixPart1!J$1,netflixPart2!$A$1:$F$1))),"Missing")} -> Documentaries, International Movies
... A221: s159 | B221: Movie | C221: Love Don't Cost a Thing | D221: Troy Byer | E221: United States | F221: {=IFERROR(_xlfn.XLOOKUP($A221,netflixPart2!$A:$A,_xlfn.CHOOSECOLS(netflixPart2!$A:$F,_xlfn.XMATCH(netflixPart1!F$1,netflixPart2!$A$1:$F$1))),"Missing")} -> 09/01/2021 | G221: {=DATE(IFERROR(_xlfn.XLOOKUP($A221,netflixPart2!$A:$A,_xlfn.CHOOSECOLS(netflixPart2!$A:$F,_xlfn.XMATCH(netflixPart1!G$1,netflixPart2!$A$1:$F$1))),"Missing"),1,1)} -> 37622 | H221: {=IFERROR(_xlfn.XLOOKUP($A221,netflixPart2!$A:$A,_xlfn.CHOOSECOLS(netflixPart2!$A:$F,_xlfn.XMATCH(netflixPart1!H$1,netflixPart2!$A$1:$F$1))),"Missing")} -> PG-13 | I221: {=IFERROR(_xlfn.XLOOKUP($A221,netflixPart2!$A:$A,_xlfn.CHOOSECOLS(netflixPart2!$A:$F,_xlfn.XMATCH(netflixPart1!I$1,netflixPart2!$A$1:$F$1))),"Missing")} -> 101 min | J221: {=IFERROR(_xlfn.XLOOKUP($A221,netflixPart2!$A:$A,_xlfn.CHOOSECOLS(netflixPart2!$A:$F,_xlfn.XMATCH(netflixPart1!J$1,netflixPart2!$A$1:$F$1))),"Missing")} -> Comedies, Romantic Movies
A222: s160 | B222: Movie | C222: Love in a Puff | D222: Pang Ho-cheung | E222: Hong Kong | F222: {=IFERROR(_xlfn.XLOOKUP($A222,netflixPart2!$A:$A,_xlfn.CHOOSECOLS(netflixPart2!$A:$F,_xlfn.XMATCH(netflixPart1!F$1,netflixPart2!$A$1:$F$1))),"Missing")} -> 09/01/2021 | G222: {=DATE(IFERROR(_xlfn.XLOOKUP($A222,netflixPart2!$A:$A,_xlfn.CHOOSECOLS(netflixPart2!$A:$F,_xlfn.XMATCH(netflixPart1!G$1,netflixPart2!$A$1:$F$1))),"Missing"),1,1)} -> 40179 | H222: {=IFERROR(_xlfn.XLOOKUP($A222,netflixPart2!$A:$A,_xlfn.CHOOSECOLS(netflixPart2!$A:$F,_xlfn.XMATCH(netflixPart1!H$1,netflixPart2!$A$1:$F$1))),"Missing")} -> TV-MA | I222: {=IFERROR(_xlfn.XLOOKUP($A222,netflixPart2!$A:$A,_xlfn.CHOOSECOLS(netflixPart2!$A:$F,_xlfn.XMATCH(netflixPart1!I$1,netflixPart2!$A$1:$F$1))),"Missing")} -> 103 min | J222: {=IFERROR(_xlfn.XLOOKUP($A222,netflixPart2!$A:$A,_xlfn.CHOOSECOLS(netflixPart2!$A:$F,_xlfn.XMATCH(netflixPart1!J$1,netflixPart2!$A$1:$F$1))),"Missing")} -> Comedies, Dramas, International Movies | K222: =_xlfn.TEXTJOIN("|",FALSE,B222:J222) -> Movie|Love in a Puff|Pang Ho-cheung|Hong Kong|09/01/2021|40179|TV-MA|103 min|Comedies, Dramas, International Movies
A223: s1463 | B223: TV Show | C223: Running Man | D223: Not Given | E223: Pakistan | F223: {=IFERROR(_xlfn.XLOOKUP($A223,netflixPart2!$A:$A,_xlfn.CHOOSECOLS(netflixPart2!$A:$F,_xlfn.XMATCH(netflixPart1!F$1,netflixPart2!$A$1:$F$1))),"Missing")} -> 01/01/2021 | G223: {=DATE(IFERROR(_xlfn.XLOOKUP($A223,netflixPart2!$A:$A,_xlfn.CHOOSECOLS(netflixPart2!$A:$F,_xlfn.XMATCH(netflixPart1!G$1,netflixPart2!$A$1:$F$1))),"Missing"),1,1)} -> 43831 | H223: {=IFERROR(_xlfn.XLOOKUP($A223,netflixPart2!$A:$A,_xlfn.CHOOSECOLS(netflixPart2!$A:$F,_xlfn.XMATCH(netflixPart1!H$1,netflixPart2!$A$1:$F$1))),"Missing")} -> TV-Y7 | I223: {=IFERROR(_xlfn.XLOOKUP($A223,netflixPart2!$A:$A,_xlfn.CHOOSECOLS(netflixPart2!$A:$F,_xlfn.XMATCH(netflixPart1!I$1,netflixPart2!$A$1:$F$1))),"Missing")} -> 1 Season | J223: {=IFERROR(_xlfn.XLOOKUP($A223,netflixPart2!$A:$A,_xlfn.CHOOSECOLS(netflixPart2!$A:$F,_xlfn.XMATCH(netflixPart1!J$1,netflixPart2!$A$1:$F$1))),"Missing")} -> Kids' TV, TV Comedies
A224: s162 | B224: Movie | C224: Mars Attacks! | D224: Tim Burton | E224: United States | F224: {=IFERROR(_xlfn.XLOOKUP($A224,netflixPart2!$A:$A,_xlfn.CHOOSECOLS(netflixPart2!$A:$F,_xlfn.XMATCH(netflixPart1!F$1,netflixPart2!$A$1:$F$1))),"Missing")} -> 09/01/2021 | G224: {=DATE(IFERROR(_xlfn.XLOOKUP($A224,netflixPart2!$A:$A,_xlfn.CHOOSECOLS(netflixPart2!$A:$F,_xlfn.XMATCH(netflixPart1!G$1,netflixPart2!$A$1:$F$1))),"Missing"),1,1)} -> 35065 | H224: {=IFERROR(_xlfn.XLOOKUP($A224,netflixPart2!$A:$A,_xlfn.CHOOSECOLS(netflixPart2!$A:$F,_xlfn.XMATCH(netflixPart1!H$1,netflixPart2!$A$1:$F$1))),"Missing")} -> PG-13 | I224: {=IFERROR(_xlfn.XLOOKUP($A224,netflixPart2!$A:$A,_xlfn.CHOOSECOLS(netflixPart2!$A:$F,_xlfn.XMATCH(netflixPart1!I$1,netflixPart2!$A$1:$F$1))),"Missing")} -> 106 min | J224: {=IFERROR(_xlfn.XLOOKUP($A224,netflixPart2!$A:$A,_xlfn.CHOOSECOLS(netflixPart2!$A:$F,_xlfn.XMATCH(netflixPart1!J$1,netflixPart2!$A$1:$F$1))),"Missing")} -> Comedies, Cult Movies, Sci-Fi & Fantasy
A225: s163 | B225: Movie | C225: Marshall | D225: Reginald Hudlin | E225: United States | F225: {=IFERROR(_xlfn.XLOOKUP($A225,netflixPart2!$A:$A,_xlfn.CHOOSECOLS(netflixPart2!$A:$F,_xlfn.XMATCH(netflixPart1!F$1,netflixPart2!$A$1:$F$1))),"Missing")} -> 09/01/2021 | G225: {=DATE(IFERROR(_xlfn.XLOOKUP($A225,netflixPart2!$A:$A,_xlfn.CHOOSECOLS(netflixPart2!$A:$F,_xlfn.XMATCH(netflixPart1!G$1,netflixPart2!$A$1:$F$1))),"Missing"),1,1)} -> 42736 | H225: {=IFERROR(_xlfn.XLOOKUP($A225,netflixPart2!$A:$A,_xlfn.CHOOSECOLS(netflixPart2!$A:$F,_xlfn.XMATCH(netflixPart1!H$1,netflixPart2!$A$1:$F$1))),"Missing")} -> PG-13 | I225: {=IFERROR(_xlfn.XLOOKUP($A225,netflixPart2!$A:$A,_xlfn.CHOOSECOLS(netflixPart2!$A:$F,_xlfn.XMATCH(netflixPart1!I$1,netflixPart2!$A$1:$F$1))),"Missing")} -> 118 min | J225: {=IFERROR(_xlfn.XLOOKUP($A225,netflixPart2!$A:$A,_xlfn.CHOOSECOLS(netflixPart2!$A:$F,_xlfn.XMATCH(netflixPart1!J$1,netflixPart2!$A$1:$F$1))),"Missing")} -> Dramas
A226: s164 | B226: Movie | C226: My Boss's Daughter | D226: David Zucker | E226: United States | F226: {=IFERROR(_xlfn.XLOOKUP($A226,netflixPart2!$A:$A,_xlfn.CHOOSECOLS(netflixPart2!$A:$F,_xlfn.XMATCH(netflixPart1!F$1,netflixPart2!$A$1:$F$1))),"Missing")} -> 09/01/2021 | G226: {=DATE(IFERROR(_xlfn.XLOOKUP($A226,netflixPart2!$A:$A,_xlfn.CHOOSECOLS(netflixPart2!$A:$F,_xlfn.XMATCH(netflixPart1!G$1,netflixPart2!$A$1:$F$1))),"Missing"),1,1)} -> 37622 | H226: {=IFERROR(_xlfn.XLOOKUP($A226,netflixPart2!$A:$A,_xlfn.CHOOSECOLS(netflixPart2!$A:$F,_xlfn.XMATCH(netflixPart1!H$1,netflixPart2!$A$1:$F$1))),"Missing")} -> R | I226: {=IFERROR(_xlfn.XLOOKUP($A226,netflixPart2!$A:$A,_xlfn.CHOOSECOLS(netflixPart2!$A:$F,_xlfn.XMATCH(netflixPart1!I$1,netflixPart2!$A$1:$F$1))),"Missing")} -> 86 min | J226: {=IFERROR(_xlfn.XLOOKUP($A226,netflixPart2!$A:$A,_xlfn.CHOOSECOLS(netflixPart2!$A:$F,_xlfn.XMATCH(netflixPart1!J$1,netflixPart2!$A$1:$F$1))),"Missing")} -> Comedies, Romantic Movies
A227: s165 | B227: Movie | C227: Mystery Men | D227: Kinka Usher | E227: United States | F227: {=IFERROR(_xlfn.XLOOKUP($A227,netflixPart2!$A:$A,_xlfn.CHOOSECOLS(netflixPart2!$A:$F,_xlfn.XMATCH(netflixPart1!F$1,netflixPart2!$A$1:$F$1))),"Missing")} -> 09/01/2021 | G227: {=DATE(IFERROR(_xlfn.XLOOKUP($A227,netflixPart2!$A:$A,_xlfn.CHOOSECOLS(netflixPart2!$A:$F,_xlfn.XMATCH(netflixPart1!G$1,netflixPart2!$A$1:$F$1))),"Missing"),1,1)} -> 36161 | H227: {=IFERROR(_xlfn.XLOOKUP($A227,netflixPart2!$A:$A,_xlfn.CHOOSECOLS(netflixPart2!$A:$F,_xlfn.XMATCH(netflixPart1!H$1,netflixPart2!$A$1:$F$1))),"Missing")} -> PG-13 | I227: {=IFERROR(_xlfn.XLOOKUP($A227,netflixPart2!$A:$A,_xlfn.CHOOSECOLS(netflixPart2!$A:$F,_xlfn.XMATCH(netflixPart1!I$1,netflixPart2!$A$1:$F$1))),"Missing")} -> 121 min | J227: {=IFERROR(_xlfn.XLOOKUP($A227,netflixPart2!$A:$A,_xlfn.CHOOSECOLS(netflixPart2!$A:$F,_xlfn.XMATCH(netflixPart1!J$1,netflixPart2!$A$1:$F$1))),"Missing")} -> Action & Adventure, Comedies
A228: s1472 | B228: Movie | C228: Best of Stand-Up 2020 | D228: Not Given | E228: Pakistan | F228: {=IFERROR(_xlfn.XLOOKUP($A228,netflixPart2!$A:$A,_xlfn.CHOOSECOLS(netflixPart2!$A:$F,_xlfn.XMATCH(netflixPart1!F$1,netflixPart2!$A$1:$F$1))),"Missing")} -> 12/31/2020 | G228: {=DATE(IFERROR(_xlfn.XLOOKUP($A228,netflixPart2!$A:$A,_xlfn.CHOOSECOLS(netflixPart2!$A:$F,_xlfn.XMATCH(netflixPart1!G$1,netflixPart2!$A$1:$F$1))),"Missing"),1,1)} -> 43831 | H228: {=IFERROR(_xlfn.XLOOKUP($A228,netflixPart2!$A:$A,_xlfn.CHOOSECOLS(netflixPart2!$A:$F,_xlfn.XMATCH(netflixPart1!H$1,netflixPart2!$A$1:$F$1))),"Missing")} -> TV-MA | I228: {=IFERROR(_xlfn.XLOOKUP($A228,netflixPart2!$A:$A,_xlfn.CHOOSECOLS(netflixPart2!$A:$F,_xlfn.XMATCH(netflixPart1!I$1,netflixPart2!$A$1:$F$1))),"Missing")} -> 77 min | J228: {=IFERROR(_xlfn.XLOOKUP($A228,netflixPart2!$A:$A,_xlfn.CHOOSECOLS(netflixPart2!$A:$F,_xlfn.XMATCH(netflixPart1!J$1,netflixPart2!$A$1:$F$1))),"Missing")} -> Stand-Up Comedy
A229: s167 | B229: Movie | C229: Once Upon a Time in America | D229: Sergio Leone | E229: Italy | F229: {=IFERROR(_xlfn.XLOOKUP($A229,netflixPart2!$A:$A,_xlfn.CHOOSECOLS(netflixPart2!$A:$F,_xlfn.XMATCH(netflixPart1!F$1,netflixPart2!$A$1:$F$1))),"Missing")} -> 09/01/2021 | G229: {=DATE(IFERROR(_xlfn.XLOOKUP($A229,netflixPart2!$A:$A,_xlfn.CHOOSECOLS(netflixPart2!$A:$F,_xlfn.XMATCH(netflixPart1!G$1,netflixPart2!$A$1:$F$1))),"Missing"),1,1)} -> 30682 | H229: {=IFERROR(_xlfn.XLOOKUP($A229,netflixPart2!$A:$A,_xlfn.CHOOSECOLS(netflixPart2!$A:$F,_xlfn.XMATCH(netflixPart1!H$1,netflixPart2!$A$1:$F$1))),"Missing")} -> R | I229: {=IFERROR(_xlfn.XLOOKUP($A229,netflixPart2!$A:$A,_xlfn.CHOOSECOLS(netflixPart2!$A:$F,_xlfn.XMATCH(netflixPart1!I$1,netflixPart2!$A$1:$F$1))),"Missing")} -> 229 min | J229: {=IFERROR(_xlfn.XLOOKUP($A229,netflixPart2!$A:$A,_xlfn.CHOOSECOLS(netflixPart2!$A:$F,_xlfn.XMATCH(netflixPart1!J$1,netflixPart2!$A$1:$F$1))),"Missing")} -> Classic Movies, Dramas
A230: s168 | B230: Movie | C230: Open Season 2 | D230: Matthew O'Callaghan, Todd Wilderman | E230: United States | F230: {=IFERROR(_xlfn.XLOOKUP($A230,netflixPart2!$A:$A,_xlfn.CHOOSECOLS(netflixPart2!$A:$F,_xlfn.XMATCH(netflixPart1!F$1,netflixPart2!$A$1:$F$1))),"Missing")} -> 09/01/2021 | G230: {=DATE(IFERROR(_xlfn.XLOOKUP($A230,netflixPart2!$A:$A,_xlfn.CHOOSECOLS(netflixPart2!$A:$F,_xlfn.XMATCH(netflixPart1!G$1,netflixPart2!$A$1:$F$1))),"Missing"),1,1)} -> 39448 | H230: {=IFERROR(_xlfn.XLOOKUP($A230,netflixPart2!$A:$A,_xlfn.CHOOSECOLS(netflixPart2!$A:$F,_xlfn.XMATCH(netflixPart1!H$1,netflixPart2!$A$1:$F$1))),"Missing")} -> PG | I230: {=IFERROR(_xlfn.XLOOKUP($A230,netflixPart2!$A:$A,_xlfn.CHOOSECOLS(netflixPart2!$A:$F,_xlfn.XMATCH(netflixPart1!I$1,netflixPart2!$A$1:$F$1))),"Missing")} -> 76 min | J230: {=IFERROR(_xlfn.XLOOKUP($A230,netflixPart2!$A:$A,_xlfn.CHOOSECOLS(netflixPart2!$A:$F,_xlfn.XMATCH(netflixPart1!J$1,netflixPart2!$A$1:$F$1))),"Missing")} -> Children & Family Movies, Comedies
A231: s169 | B231: Movie | C231: Osmosis Jones | D231: Bobby Farrelly, Peter Farrelly | E231: United States | F231: {=IFERROR(_xlfn.XLOOKUP($A231,netflixPart2!$A:$A,_xlfn.CHOOSECOLS(netflixPart2!$A:$F,_xlfn.XMATCH(netflixPart1!F$1,netflixPart2!$A$1:$F$1))),"Missing")} -> 09/01/2021 | G231: {=DATE(IFERROR(_xlfn.XLOOKUP($A231,netflixPart2!$A:$A,_xlfn.CHOOSECOLS(netflixPart2!$A:$F,_xlfn.XMATCH(netflixPart1!G$1,netflixPart2!$A$1:$F$1))),"Missing"),1,1)} -> 36892 | H231: {=IFERROR(_xlfn.XLOOKUP($A231,netflixPart2!$A:$A,_xlfn.CHOOSECOLS(netflixPart2!$A:$F,_xlfn.XMATCH(netflixPart1!H$1,netflixPart2!$A$1:$F$1))),"Missing")} -> PG | I231: {=IFERROR(_xlfn.XLOOKUP($A231,netflixPart2!$A:$A,_xlfn.CHOOSECOLS(netflixPart2!$A:$F,_xlfn.XMATCH(netflixPart1!I$1,netflixPart2!$A$1:$F$1))),"Missing")} -> 95 min | J231: {=IFERROR(_xlfn.XLOOKUP($A231,netflixPart2!$A:$A,_xlfn.CHOOSECOLS(netflixPart2!$A:$F,_xlfn.XMATCH(netflixPart1!J$1,netflixPart2!$A$1:$F$1))),"Missing")} -> Action & Adventure, Children & Family Movies, Comedies
A232: s170 | B232: Movie | C232: Poseidon | D232: Wolfgang Petersen | E232: United States | F232: {=IFERROR(_xlfn.XLOOKUP($A232,netflixPart2!$A:$A,_xlfn.CHOOSECOLS(netflixPart2!$A:$F,_xlfn.XMATCH(netflixPart1!F$1,netflixPart2!$A$1:$F$1))),"Missing")} -> 09/01/2021 | G232: {=DATE(IFERROR(_xlfn.XLOOKUP($A232,netflixPart2!$A:$A,_xlfn.CHOOSECOLS(netflixPart2!$A:$F,_xlfn.XMATCH(netflixPart1!G$1,netflixPart2!$A$1:$F$1))),"Missing"),1,1)} -> 38718 | H232: {=IFERROR(_xlfn.XLOOKUP($A232,netflixPart2!$A:$A,_xlfn.CHOOSECOLS(netflixPart2!$A:$F,_xlfn.XMATCH(netflixPart1!H$1,netflixPart2!$A$1:$F$1))),"Missing")} -> PG-13 | I232: {=IFERROR(_xlfn.XLOOKUP($A232,netflixPart2!$A:$A,_xlfn.CHOOSECOLS(netflixPart2!$A:$F,_xlfn.XMATCH(netflixPart1!I$1,netflixPart2!$A$1:$F$1))),"Missing")} -> 98 min | J232: {=IFERROR(_xlfn.XLOOKUP($A232,netflixPart2!$A:$A,_xlfn.CHOOSECOLS(netflixPart2!$A:$F,_xlfn.XMATCH(netflixPart1!J$1,netflixPart2!$A$1:$F$1))),"Missing")} -> Action & Adventure, Dramas
A233: s1483 | B233: TV Show | C233: Transformers: War for Cybertron: Earthrise | D233: Not Given | E233: Pakistan | F233: {=IFERROR(_xlfn.XLOOKUP($A233,netflixPart2!$A:$A,_xlfn.CHOOSECOLS(netflixPart2!$A:$F,_xlfn.XMATCH(netflixPart1!F$1,netflixPart2!$A$1:$F$1))),"Missing")} -> 12/30/2020 | G233: {=DATE(IFERROR(_xlfn.XLOOKUP($A233,netflixPart2!$A:$A,_xlfn.CHOOSECOLS(netflixPart2!$A:$F,_xlfn.XMATCH(netflixPart1!G$1,netflixPart2!$A$1:$F$1))),"Missing"),1,1)} -> 43831 | H233: {=IFERROR(_xlfn.XLOOKUP($A233,netflixPart2!$A:$A,_xlfn.CHOOSECOLS(netflixPart2!$A:$F,_xlfn.XMATCH(netflixPart1!H$1,netflixPart2!$A$1:$F$1))),"Missing")} -> TV-Y7 | I233: {=IFERROR(_xlfn.XLOOKUP($A233,netflixPart2!$A:$A,_xlfn.CHOOSECOLS(netflixPart2!$A:$F,_xlfn.XMATCH(netflixPart1!I$1,netflixPart2!$A$1:$F$1))),"Missing")} -> 1 Season | J233: {=IFERROR(_xlfn.XLOOKUP($A233,netflixPart2!$A:$A,_xlfn.CHOOSECOLS(netflixPart2!$A:$F,_xlfn.XMATCH(netflixPart1!J$1,netflixPart2!$A$1:$F$1))),"Missing")} -> Anime Series
...

Sheet draft- duplications
A1: show_id | B1: type | C1: title | D1: director | E1: country | F1: date_added | G1: release_year | H1: rating | I1: duration | J1: listed_in | K1: duplication
A2: s160 | B2: Movie | C2: Love in a Puff | D2: Pang Ho-cheung | E2: Hong Kong | F2: 09/01/2021 | G2: 40179 | H2: TV-MA | I2: 103 min | J2: Comedies, Dramas, International Movies | K2: Movie|Love in a Puff|Pang Ho-cheung|Hong Kong|09/01/2021|40179|TV-MA|103 min|Comedies, Dramas, International Movies
A3: s3997 | B3: TV Show | C3: 09-Feb | D3: Not Given | E3: Pakistan | F3: 3/20/2019 | G3: 43101 | H3: TV-14 | I3: 1 Season | J3: International TV Shows, TV Dramas | K3: TV Show|09-Feb|Not Given|Pakistan|3/20/2019|43101|TV-14|1 Season|International TV Shows, TV Dramas
A4: s304 | B4: Movie | C4: Esperando la carroza | D4: Alejandro Doria | E4: Argentina | F4: 08/05/2021 | G4: 31048 | H4: TV-MA | I4: 95 min | J4: Comedies, Cult Movies, International Movies | K4: Movie|Esperando la carroza|Alejandro Doria|Argentina|08/05/2021|31048|TV-MA|95 min|Comedies, Cult Movies, International Movies
A5: s5965 | B5: TV Show | C5: 09-Feb | D5: Not Given | E5: Pakistan | F5: 3/20/2019 | G5: 43101 | H5: TV-14 | I5: 1 Season | J5: International TV Shows, TV Dramas | K5: TV Show|09-Feb|Not Given|Pakistan|3/20/2019|43101|TV-14|1 Season|International TV Shows, TV Dramas
A6: s3963 | B6: Movie | C6: 15-Aug | D6: Swapnaneel Jayakar | E6: India | F6: 3/29/2019 | G6: 43466 | H6: TV-14 | I6: 124 min | J6: Comedies, Dramas, Independent Movies | K6: Movie|15-Aug|Swapnaneel Jayakar|India|3/29/2019|43466|TV-14|124 min|Comedies, Dramas, Independent Movies
A7: s4523 | B7: Movie | C7: 22-Jul | D7: Paul Greengrass | E7: Norway | F7: 10/10/2018 | G7: 43101 | H7: R | I7: 144 min | J7: Dramas, Thrillers | K7: Movie|22-Jul|Paul Greengrass|Norway|10/10/2018|43101|R|144 min|Dramas, Thrillers
A8: s5034 | B8: Movie | C8: FullMetal Alchemist | D8: Fumihiko Sori | E8: Japan | F8: 2/19/2018 | G8: 42736 | H8: TV-PG | I8: 134 min | J8: Action & Adventure, Dramas, International Movies | K8: Movie|FullMetal Alchemist|Fumihiko Sori|Japan|2/19/2018|42736|TV-PG|134 min|Action & Adventure, Dramas, International Movies
A9: s5319 | B9: Movie | C9: Death Note | D9: Adam Wingard | E9: United States | F9: 8/25/2017 | G9: 42736 | H9: TV-MA | I9: 100 min | J9: Horror Movies, Thrillers | K9: Movie|Death Note|Adam Wingard|United States|8/25/2017|42736|TV-MA|100 min|Horror Movies, Thrillers
A10: s5966 | B10: Movie | C10: 22-Jul | D10: Paul Greengrass | E10: Norway | F10: 10/10/2018 | G10: 43101 | H10: R | I10: 144 min | J10: Dramas, Thrillers | K10: Movie|22-Jul|Paul Greengrass|Norway|10/10/2018|43101|R|144 min|Dramas, Thrillers
A11: s5967 | B11: Movie | C11: 15-Aug | D11: Swapnaneel Jayakar | E11: India | F11: 3/29/2019 | G11: 43466 | H11: TV-14 | I11: 124 min | J11: Comedies, Dramas, Independent Movies | K11: Movie|15-Aug|Swapnaneel Jayakar|India|3/29/2019|43466|TV-14|124 min|Comedies, Dramas, Independent Movies
A12: s6706 | B12: Movie | C12: Esperando La Carroza | D12: Alejandro Doria | E12: Argentina | F12: 7/15/2018 | G12: 31048 | H12: NR | I12: 95 min | J12: Comedies, Cult Movies, International Movies | K12: Movie|Esperando La Carroza|Alejandro Doria|Argentina|7/15/2018|31048|NR|95 min|Comedies, Cult Movies, International Movies
A13: s7346 | B13: Movie | C13: Love In A Puff | D13: Pang Ho-cheung | E13: Hong Kong | F13: 08/01/2018 | G13: 40179 | H13: TV-MA | I13: 103 min | J13: Comedies, Dramas, International Movies | K13: Movie|Love In A Puff|Pang Ho-cheung|Hong Kong|08/01/2018|40179|TV-MA|103 min|Comedies, Dramas, International Movies
... A17: s8023 | B17: TV Show | C17: Sin Senos sí Hay Paraíso | D17: Not Given | E17: United States | F17: 01/11/2019 | G17: 43101 | H17: TV-MA | I17: 3 Seasons | J17: International TV Shows, Spanish-Language TV Shows, TV Dramas | K17: TV Show|Sin Senos sí Hay Paraíso|Not Given|United States|01/11/2019|43101|TV-MA|3 Seasons|International TV Shows, Spanish-Language TV Shows, TV Dramas
